Workbook

Sheet data_2015-2020
A1: country | B1: year | C1: rgdpna | D1: rnna | E1: emp | F1: rkna | G1: irr | H1: delta | I1: xr | J1: hc | K1: rwtfpna | L1: t | M1: i | N1: continente | O1: región | P1: Americas | Q1: Europe | R1: Asia | S1: Africa | T1: Oceania | U1: Caribbean | V1: Middle Africa | W1: Southern Europe | X1: Western Asia | Y1: South America | Z1: Australia and New Zealand | AA1: Western Europe | AB1: Eastern Africa | AC1: Western Africa | AD1: Southern Asia | AE1: Eastern Europe | AF1: Central America | AG1: Northern America | AH1: South-eastern Asia | AI1: Southern Africa | AJ1: Eastern Asia | AK1: Northern Europe | AL1: Northern Africa | AM1: Melanesia | AN1: Central Asia
A2: Aruba | B2: 2015 | C2: 4032.4707 | D2: 21116.465 | E2: 0.046936773 | F2: 0.91074914 | G2: 0.049298905 | H2: 0.033945106 | I2: 1.79 | L2: =B2-2014 -> 1 | M2: =VLOOKUP($A2,Sheet2!$B$2:$E$186,2,FALSE) -> 1 | N2: Americas | O2: Caribbean | P2: 1 | Q2: 0 | R2: 0 | S2: 0 | T2: 0 | U2: 1 | V2: 0 | W2: 0 | X2: 0 | Y2: 0 | Z2: 0 | AA2: 0 | AB2: 0 | AC2: 0 | AD2: 0 | AE2: 0 | AF2: 0 | AG2: 0 | AH2: 0 | AI2: 0 | AJ2: 0 | AK2: 0 | AL2: 0 | AM2: 0 | AN2: 0
A3: Aruba | B3: 2016 | C3: 4101.814 | D3: 21373.148 | E3: 0.047294036 | F3: 0.92656702 | G3: 0.052998036 | H3: 0.034145255 | I3: 1.79 | L3: =B3-2014 -> 2 | M3: =VLOOKUP(A3,Sheet2!$B$2:$E$186,2,FALSE) -> 1 | N3: Americas | O3: Caribbean | P3: 1 | Q3: 0 | R3: 0 | S3: 0 | T3: 0 | U3: 1 | V3: 0 | W3: 0 | X3: 0 | Y3: 0 | Z3: 0 | AA3: 0 | AB3: 0 | AC3: 0 | AD3: 0 | AE3: 0 | AF3: 0 | AG3: 0 | AH3: 0 | AI3: 0 | AJ3: 0 | AK3: 0 | AL3: 0 | AM3: 0 | AN3: 0
A4: Aruba | B4: 2017 | C4: 4390.9316 | D4: 21666.68 | E4: 0.047633726 | F4: 0.94581091 | G4: 0.055784095 | H4: 0.034465384 | I4: 1.79 | L4: =B4-2014 -> 3 | M4: =VLOOKUP(A4,Sheet2!$B$2:$E$186,2,FALSE) -> 1 | N4: Americas | O4: Caribbean | P4: 1 | Q4: 0 | R4: 0 | S4: 0 | T4: 0 | U4: 1 | V4: 0 | W4: 0 | X4: 0 | Y4: 0 | Z4: 0 | AA4: 0 | AB4: 0 | AC4: 0 | AD4: 0 | AE4: 0 | AF4: 0 | AG4: 0 | AH4: 0 | AI4: 0 | AJ4: 0 | AK4: 0 | AL4: 0 | AM4: 0 | AN4: 0
A5: Aruba | B5: 2018 | C5: 4496.186 | D5: 21968.637 | E5: 0.047949538 | F5: 0.96592063 | G5: 0.047910463 | H5: 0.03487809 | I5: 1.79 | L5: =B5-2014 -> 4 | M5: =VLOOKUP(A5,Sheet2!$B$2:$E$186,2,FALSE) -> 1 | N5: Americas | O5: Caribbean | P5: 1 | Q5: 0 | R5: 0 | S5: 0 | T5: 0 | U5: 1 | V5: 0 | W5: 0 | X5: 0 | Y5: 0 | Z5: 0 | AA5: 0 | AB5: 0 | AC5: 0 | AD5: 0 | AE5: 0 | AF5: 0 | AG5: 0 | AH5: 0 | AI5: 0 | AJ5: 0 | AK5: 0 | AL5: 0 | AM5: 0 | AN5: 0
A6: Aruba | B6: 2019 | C6: 4395.8115 | D6: 22266.496 | E6: 0.048239671 | F6: 0.98533988 | G6: 0.047444623 | H6: 0.035302024 | I6: 1.79 | L6: =B6-2014 -> 5 | M6: =VLOOKUP(A6,Sheet2!$B$2:$E$186,2,FALSE) -> 1 | N6: Americas | O6: Caribbean | P6: 1 | Q6: 0 | R6: 0 | S6: 0 | T6: 0 | U6: 1 | V6: 0 | W6: 0 | X6: 0 | Y6: 0 | Z6: 0 | AA6: 0 | AB6: 0 | AC6: 0 | AD6: 0 | AE6: 0 | AF6: 0 | AG6: 0 | AH6: 0 | AI6: 0 | AJ6: 0 | AK6: 0 | AL6: 0 | AM6: 0 | AN6: 0
A7: Aruba | B7: 2020 | C7: 3243.5891 | D7: 22325.037 | E7: 0.048385642 | F7: 0.99136049 | G7: 0.021925922 | H7: 0.035575263 | I7: 1.79 | L7: =B7-2014 -> 6 | M7: =VLOOKUP(A7,Sheet2!$B$2:$E$186,2,FALSE) -> 1 | N7: Americas | O7: Caribbean | P7: 1 | Q7: 0 | R7: 0 | S7: 0 | T7: 0 | U7: 1 | V7: 0 | W7: 0 | X7: 0 | Y7: 0 | Z7: 0 | AA7: 0 | AB7: 0 | AC7: 0 | AD7: 0 | AE7: 0 | AF7: 0 | AG7: 0 | AH7: 0 | AI7: 0 | AJ7: 0 | AK7: 0 | AL7: 0 | AM7: 0 | AN7: 0
A8: Angola | B8: 2015 | C8: 236550.8 | D8: 633460.12 | E8: 12.960231 | F8: 0.95452279 | G8: 0.064976379 | H8: 0.048470814 | I8: 120.0607 | J8: 1.452803 | K8: 1.3628134 | L8: =B8-2014 -> 1 | M8: =VLOOKUP(A8,Sheet2!$B$2:$E$186,2,FALSE) -> 2 | N8: Africa | O8: Middle Africa | P8: 0 | Q8: 0 | R8: 0 | S8: 1 | T8: 0 | U8: 0 | V8: 1 | W8: 0 | X8: 0 | Y8: 0 | Z8: 0 | AA8: 0 | AB8: 0 | AC8: 0 | AD8: 0 | AE8: 0 | AF8: 0 | AG8: 0 | AH8: 0 | AI8: 0 | AJ8: 0 | AK8: 0 | AL8: 0 | AM8: 0 | AN8: 0
A9: Angola | B9: 2016 | C9: 230400.47 | D9: 651413.44 | E9: 13.361247 | F9: 0.97432673 | G9: 0.067191809 | H9: 0.047874562 | I9: 163.65643 | J9: 1.460044 | K9: 1.2608935 | L9: =B9-2014 -> 2 | M9: =VLOOKUP(A9,Sheet2!$B$2:$E$186,2,FALSE) -> 2 | N9: Africa | O9: Middle Africa | P9: 0 | Q9: 0 | R9: 0 | S9: 1 | T9: 0 | U9: 0 | V9: 1 | W9: 0 | X9: 0 | Y9: 0 | Z9: 0 | AA9: 0 | AB9: 0 | AC9: 0 | AD9: 0 | AE9: 0 | AF9: 0 | AG9: 0 | AH9: 0 | AI9: 0 | AJ9: 0 | AK9: 0 | AL9: 0 | AM9: 0 | AN9: 0
A10: Angola | B10: 2017 | C10: 230170.08 | D10: 659431.12 | E10: 13.786605 | F10: 0.97949493 | G10: 0.055525072 | H10: 0.046948642 | I10: 165.91595 | J10: 1.4673212 | K10: 1.1825011 | L10: =B10-2014 -> 3 | M10: =VLOOKUP(A10,Sheet2!$B$2:$E$186,2,FALSE) -> 2 | N10: Africa | O10: Middle Africa | P10: 0 | Q10: 0 | R10: 0 | S10: 1 | T10: 0 | U10: 0 | V10: 1 | W10: 0 | X10: 0 | Y10: 0 | Z10: 0 | AA10: 0 | AB10: 0 | AC10: 0 | AD10: 0 | AE10: 0 | AF10: 0 | AG10: 0 | AH10: 0 | AI10: 0 | AJ10: 0 | AK10: 0 | AL10: 0 | AM10: 0 | AN10: 0
A11: Angola | B11: 2018 | C11: 227177.88 | D11: 665065.56 | E11: 14.224143 | F11: 0.98284638 | G11: 0.088185951 | H11: 0.04623979 | I11: 252.85575 | J11: 1.4746345 | K11: 1.1222218 | L11: =B11-2014 -> 4 | M11: =VLOOKUP(A11,Sheet2!$B$2:$E$186,2,FALSE) -> 2 | N11: Africa | O11: Middle Africa | P11: 0 | Q11: 0 | R11: 0 | S11: 1 | T11: 0 | U11: 0 | V11: 1 | W11: 0 | X11: 0 | Y11: 0 | Z11: 0 | AA11: 0 | AB11: 0 | AC11: 0 | AD11: 0 | AE11: 0 | AF11: 0 | AG11: 0 | AH11: 0 | AI11: 0 | AJ11: 0 | AK11: 0 | AL11: 0 | AM11: 0 | AN11: 0
A12: Angola | B12: 2019 | C12: 225587.61 | D12: 672279.19 | E12: 14.692121 | F12: 0.98982102 | G12: 0.1039909 | H12: 0.045704171 | I12: 364.8258 | J12: 1.4819844 | K12: 1.0870256 | L12: =B12-2014 -> 5 | M12: =VLOOKUP(A12,Sheet2!$B$2:$E$186,2,FALSE) -> 2 | N12: Africa | O12: Middle Africa | P12: 0 | Q12: 0 | R12: 0 | S12: 1 | T12: 0 | U12: 0 | V12: 1 | W12: 0 | X12: 0 | Y12: 0 | Z12: 0 | AA12: 0 | AB12: 0 | AC12: 0 | AD12: 0 | AE12: 0 | AF12: 0 | AG12: 0 | AH12: 0 | AI12: 0 | AJ12: 0 | AK12: 0 | AL12: 0 | AM12: 0 | AN12: 0
A13: Angola | B13: 2020 | C13: 212868.47 | D13: 677214.19 | E13: 15.093855 | F13: 0.99248093 | G13: 0.14851917 | H13: 0.04503566 | I13: 578.25878 | J13: 1.4893708 | K13: 1.0176498 | L13: =B13-2014 -> 6 | M13: =VLOOKUP(A13,Sheet2!$B$2:$E$186,2,FALSE) -> 2 | N13: Africa | O13: Middle Africa | P13: 0 | Q13: 0 | R13: 0 | S13: 1 | T13: 0 | U13: 0 | V13: 1 | W13: 0 | X13: 0 | Y13: 0 | Z13: 0 | AA13: 0 | AB13: 0 | AC13: 0 | AD13: 0 | AE13: 0 | AF13: 0 | AG13: 0 | AH13: 0 | AI13: 0 | AJ13: 0 | AK13: 0 | AL13: 0 | AM13: 0 | AN13: 0
A14: Anguilla | B14: 2015 | C14: 329.08401 | D14: 3546.1633 | H14: 0.026040448 | I14: 2.7 | L14: =B14-2014 -> 1 | M14: =VLOOKUP(A14,Sheet2!$B$2:$E$186,2,FALSE) -> 3 | N14: Americas | O14: Caribbean | P14: 1 | Q14: 0 | R14: 0 | S14: 0 | T14: 0 | U14: 1 | V14: 0 | W14: 0 | X14: 0 | Y14: 0 | Z14: 0 | AA14: 0 | AB14: 0 | AC14: 0 | AD14: 0 | AE14: 0 | AF14: 0 | AG14: 0 | AH14: 0 | AI14: 0 | AJ14: 0 | AK14: 0 | AL14: 0 | AM14: 0 | AN14: 0
A15: Anguilla | B15: 2016 | C15: 314.61246 | D15: 3592.6704 | H15: 0.025143981 | I15: 2.7 | L15: =B15-2014 -> 2 | M15: =VLOOKUP(A15,Sheet2!$B$2:$E$186,2,FALSE) -> 3 | N15: Americas | O15: Caribbean | P15: 1 | Q15: 0 | R15: 0 | S15: 0 | T15: 0 | U15: 1 | V15: 0 | W15: 0 | X15: 0 | Y15: 0 | Z15: 0 | AA15: 0 | AB15: 0 | AC15: 0 | AD15: 0 | AE15: 0 | AF15: 0 | AG15: 0 | AH15: 0 | AI15: 0 | AJ15: 0 | AK15: 0 | AL15: 0 | AM15: 0 | AN15: 0
A16: Anguilla | B16: 2017 | C16: 297.13239 | D16: 3638.699 | H16: 0.024726143 | I16: 2.7 | L16: =B16-2014 -> 3 | M16: =VLOOKUP(A16,Sheet2!$B$2:$E$186,2,FALSE) -> 3 | N16: Americas | O16: Caribbean | P16: 1 | Q16: 0 | R16: 0 | S16: 0 | T16: 0 | U16: 1 | V16: 0 | W16: 0 | X16: 0 | Y16: 0 | Z16: 0 | AA16: 0 | AB16: 0 | AC16: 0 | AD16: 0 | AE16: 0 | AF16: 0 | AG16: 0 | AH16: 0 | AI16: 0 | AJ16: 0 | AK16: 0 | AL16: 0 | AM16: 0 | AN16: 0
A17: Anguilla | B17: 2018 | C17: 320.89227 | D17: 3851.853 | H17: 0.025454829 | I17: 2.7 | L17: =B17-2014 -> 4 | M17: =VLOOKUP(A17,Sheet2!$B$2:$E$186,2,FALSE) -> 3 | N17: Americas | O17: Caribbean | P17: 1 | Q17: 0 | R17: 0 | S17: 0 | T17: 0 | U17: 1 | V17: 0 | W17: 0 | X17: 0 | Y17: 0 | Z17: 0 | AA17: 0 | AB17: 0 | AC17: 0 | AD17: 0 | AE17: 0 | AF17: 0 | AG17: 0 | AH17: 0 | AI17: 0 | AJ17: 0 | AK17: 0 | AL17: 0 | AM17: 0 | AN17: 0
A18: Anguilla | B18: 2019 | C18: 342.03168 | D18: 3890.531 | H18: 0.025963368 | I18: 2.7 | L18: =B18-2014 -> 5 | M18: =VLOOKUP(A18,Sheet2!$B$2:$E$186,2,FALSE) -> 3 | N18: Americas | O18: Caribbean | P18: 1 | Q18: 0 | R18: 0 | S18: 0 | T18: 0 | U18: 1 | V18: 0 | W18: 0 | X18: 0 | Y18: 0 | Z18: 0 | AA18: 0 | AB18: 0 | AC18: 0 | AD18: 0 | AE18: 0 | AF18: 0 | AG18: 0 | AH18: 0 | AI18: 0 | AJ18: 0 | AK18: 0 | AL18: 0 | AM18: 0 | AN18: 0
A19: Anguilla | B19: 2020 | C19: 242.52054 | D19: 3925.0625 | H19: 0.025695989 | I19: 2.7 | L19: =B19-2014 -> 6 | M19: =VLOOKUP(A19,Sheet2!$B$2:$E$186,2,FALSE) -> 3 | N19: Americas | O19: Caribbean | P19: 1 | Q19: 0 | R19: 0 | S19: 0 | T19: 0 | U19: 1 | V19: 0 | W19: 0 | X19: 0 | Y19: 0 | Z19: 0 | AA19: 0 | AB19: 0 | AC19: 0 | AD19: 0 | AE19: 0 | AF19: 0 | AG19: 0 | AH19: 0 | AI19: 0 | AJ19: 0 | AK19: 0 | AL19: 0 | AM19: 0 | AN19: 0
A20: Albania | B20: 2015 | C20: 35266.328 | D20: 202508.81 | E20: 0.98453122 | F20: 0.8370133 | G20: 0.0099999998 | H20: 0.028407658 | I20: 125.96167 | J20: 2.9801273 | K20: 1.0859904 | L20: =B20-2014 -> 1 | M20: =VLOOKUP(A20,Sheet2!$B$2:$E$186,2,FALSE) -> 4 | N20: Europe | O20: Southern Europe | P20: 0 | Q20: 1 | R20: 0 | S20: 0 | T20: 0 | U20: 0 | V20: 0 | W20: 1 | X20: 0 | Y20: 0 | Z20: 0 | AA20: 0 | AB20: 0 | AC20: 0 | AD20: 0 | AE20: 0 | AF20: 0 | AG20: 0 | AH20: 0 | AI20: 0 | AJ20: 0 | AK20: 0 | AL20: 0 | AM20: 0 | AN20: 0
A21: Albania | B21: 2016 | C21: 36435.223 | D21: 208733.62 | E21: 1.0445851 | F21: 0.86440355 | G21: 0.0099999998 | H21: 0.028467104 | I21: 124.1425 | J21: 2.9779167 | K21: 1.0072654 | L21: =B21-2014 -> 2 | M21: =VLOOKUP(A21,Sheet2!$B$2:$E$186,2,FALSE) -> 4 | N21: Europe | O21: Southern Europe | P21: 0 | Q21: 1 | R21: 0 | S21: 0 | T21: 0 | U21: 0 | V21: 0 | W21: 1 | X21: 0 | Y21: 0 | Z21: 0 | AA21: 0 | AB21: 0 | AC21: 0 | AD21: 0 | AE21: 0 | AF21: 0 | AG21: 0 | AH21: 0 | AI21: 0 | AJ21: 0 | AK21: 0 | AL21: 0 | AM21: 0 | AN21: 0
A22: Albania | B22: 2017 | C22: 37820.648 | D22: 215490.81 | E22: 1.0862823 | F22: 0.89211684 | G22: 0.0099999998 | H22: 0.028564056 | I22: 119.1 | J22: 2.9757078 | K22: 0.98870152 | L22: =B22-2014 -> 3 | M22: =VLOOKUP(A22,Sheet2!$B$2:$E$186,2,FALSE) -> 4 | N22: Europe | O22: Southern Europe | P22: 0 | Q22: 1 | R22: 0 | S22: 0 | T22: 0 | U22: 0 | V22: 0 | W22: 1 | X22: 0 | Y22: 0 | Z22: 0 | AA22: 0 | AB22: 0 | AC22: 0 | AD22: 0 | AE22: 0 | AF22: 0 | AG22: 0 | AH22: 0 | AI22: 0 | AJ22: 0 | AK22: 0 | AL22: 0 | AM22: 0 | AN22: 0
A23: Albania | B23: 2018 | C23: 39340.648 | D23: 222377.05 | E23: 1.1297612 | F23: 0.91985965 | G23: 0.042504009 | H23: 0.028637392 | I23: 107.98917 | J23: 2.982733 | K23: 0.96123201 | L23: =B23-2014 -> 4 | M23: =VLOOKUP(A23,Sheet2!$B$2:$E$186,2,FALSE) -> 4 | N23: Europe | O23: Southern Europe | P23: 0 | Q23: 1 | R23: 0 | S23: 0 | T23: 0 | U23: 0 | V23: 0 | W23: 1 | X23: 0 | Y23: 0 | Z23: 0 | AA23: 0 | AB23: 0 | AC23: 0 | AD23: 0 | AE23: 0 | AF23: 0 | AG23: 0 | AH23: 0 | AI23: 0 | AJ23: 0 | AK23: 0 | AL23: 0 | AM23: 0 | AN23: 0
A24: Albania | B24: 2019 | C24: 40161.957 | D24: 228637.81 | E24: 1.1612085 | F24: 0.94402945 | G24: 0.041939247 | H24: 0.028646111 | I24: 109.85083 | J24: 2.9897988 | K24: 0.94758809 | L24: =B24-2014 -> 5 | M24: =VLOOKUP(A24,Sheet2!$B$2:$E$186,2,FALSE) -> 4 | N24: Europe | O24: Southern Europe | P24: 0 | Q24: 1 | R24: 0 | S24: 0 | T24: 0 | U24: 0 | V24: 0 | W24: 1 | X24: 0 | Y24: 0 | Z24: 0 | AA24: 0 | AB24: 0 | AC24: 0 | AD24: 0 | AE24: 0 | AF24: 0 | AG24: 0 | AH24: 0 | AI24: 0 | AJ24: 0 | AK24: 0 | AL24: 0 | AM24: 0 | AN24: 0
A25: Albania | B25: 2020 | C25: 38835.777 | D25: 234575.39 | E25: 1.1091212 | F25: 0.96601796 | G25: 0.039108142 | H25: 0.028539147 | I25: 108.65 | J25: 2.9969051 | K25: 0.9754585 | L25: =B25-2014 -> 6 | M25: =VLOOKUP(A25,Sheet2!$B$2:$E$186,2,FALSE) -> 4 | N25: Europe | O25: Southern Europe | P25: 0 | Q25: 1 | R25: 0 | S25: 0 | T25: 0 | U25: 0 | V25: 0 | W25: 1 | X25: 0 | Y25: 0 | Z25: 0 | AA25: 0 | AB25: 0 | AC25: 0 | AD25: 0 | AE25: 0 | AF25: 0 | AG25: 0 | AH25: 0 | AI25: 0 | AJ25: 0 | AK25: 0 | AL25: 0 | AM25: 0 | AN25: 0
A26: United Arab Emirates | B26: 2015 | C26: 658130.94 | D26: 4665240.5 | E26: 5.7929506 | H26: 0.037582174 | I26: 3.6725 | J26: 2.8614409 | L26: =B26-2014 -> 1 | M26: =VLOOKUP(A26,Sheet2!$B$2:$E$186,2,FALSE) -> 5 | N26: Asia | O26: Western Asia | P26: 0 | Q26: 0 | R26: 1 | S26: 0 | T26: 0 | U26: 0 | V26: 0 | W26: 0 | X26: 1 | Y26: 0 | Z26: 0 | AA26: 0 | AB26: 0 | AC26: 0 | AD26: 0 | AE26: 0 | AF26: 0 | AG26: 0 | AH26: 0 | AI26: 0 | AJ26: 0 | AK26: 0 | AL26: 0 | AM26: 0 | AN26: 0
A27: United Arab Emirates | B27: 2016 | C27: 694732.88 | D27: 4863628.5 | E27: 5.8849597 | H27: 0.038047053 | I27: 3.6725 | J27: 2.8911457 | L27: =B27-2014 -> 2 | M27: =VLOOKUP(A27,Sheet2!$B$2:$E$186,2,FALSE) -> 5 | N27: Asia | O27: Western Asia | P27: 0 | Q27: 0 | R27: 1 | S27: 0 | T27: 0 | U27: 0 | V27: 0 | W27: 0 | X27: 1 | Y27: 0 | Z27: 0 | AA27: 0 | AB27: 0 | AC27: 0 | AD27: 0 | AE27: 0 | AF27: 0 | AG27: 0 | AH27: 0 | AI27: 0 | AJ27: 0 | AK27: 0 | AL27: 0 | AM27: 0 | AN27: 0
A28: United Arab Emirates | B28: 2017 | C28: 699839.62 | D28: 5015024 | E28: 5.9148078 | H28: 0.038230751 | I28: 3.6725 | J28: 3.1160605 | L28: =B28-2014 -> 3 | M28: =VLOOKUP(A28,Sheet2!$B$2:$E$186,2,FALSE) -> 5 | N28: Asia | O28: Western Asia | P28: 0 | Q28: 0 | R28: 1 | S28: 0 | T28: 0 | U28: 0 | V28: 0 | W28: 0 | X28: 1 | Y28: 0 | Z28: 0 | AA28: 0 | AB28: 0 | AC28: 0 | AD28: 0 | AE28: 0 | AF28: 0 | AG28: 0 | AH28: 0 | AI28: 0 | AJ28: 0 | AK28: 0 | AL28: 0 | AM28: 0 | AN28: 0
A29: United Arab Emirates | B29: 2018 | C29: 709034.88 | D29: 5142086.5 | E29: 5.9997139 | H29: 0.037886046 | I29: 3.6725 | J29: 3.1974719 | L29: =B29-2014 -> 4 | M29: =VLOOKUP(A29,Sheet2!$B$2:$E$186,2,FALSE) -> 5 | N29: Asia | O29: Western Asia | P29: 0 | Q29: 0 | R29: 1 | S29: 0 | T29: 0 | U29: 0 | V29: 0 | W29: 0 | X29: 1 | Y29: 0 | Z29: 0 | AA29: 0 | AB29: 0 | AC29: 0 | AD29: 0 | AE29: 0 | AF29: 0 | AG29: 0 | AH29: 0 | AI29: 0 | AJ29: 0 | AK29: 0 | AL29: 0 | AM29: 0 | AN29: 0
A30: United Arab Emirates | B30: 2019 | C30: 716893.44 | D30: 5297392 | E30: 6.0639725 | H30: 0.03722471 | I30: 3.6725 | J30: 3.2389719 | L30: =B30-2014 -> 5 | M30: =VLOOKUP(A30,Sheet2!$B$2:$E$186,2,FALSE) -> 5 | N30: Asia | O30: Western Asia | P30: 0 | Q30: 0 | R30: 1 | S30: 0 | T30: 0 | U30: 0 | V30: 0 | W30: 0 | X30: 1 | Y30: 0 | Z30: 0 | AA30: 0 | AB30: 0 | AC30: 0 | AD30: 0 | AE30: 0 | AF30: 0 | AG30: 0 | AH30: 0 | AI30: 0 | AJ30: 0 | AK30: 0 | AL30: 0 | AM30: 0 | AN30: 0
A31: United Arab Emirates | B31: 2020 | C31: 681356.69 | D31: 5393252.5 | E31: 5.9532986 | H31: 0.036395762 | I31: 3.6725 | J31: 3.2469378 | L31: =B31-2014 -> 6 | M31: =VLOOKUP(A31,Sheet2!$B$2:$E$186,2,FALSE) -> 5 | N31: Asia | O31: Western Asia | P31: 0 | Q31: 0 | R31: 1 | S31: 0 | T31: 0 | U31: 0 | V31: 0 | W31: 0 | X31: 1 | Y31: 0 | Z31: 0 | AA31: 0 | AB31: 0 | AC31: 0 | AD31: 0 | AE31: 0 | AF31: 0 | AG31: 0 | AH31: 0 | AI31: 0 | AJ31: 0 | AK31: 0 | AL31: 0 | AM31: 0 | AN31: 0
A32: Argentina | B32: 2015 | C32: 1230329.1 | D32: 4277609 | E32: 19.85445 | F32: 0.9085561 | G32: 0.12151588 | H32: 0.03857227 | I32: 9.2331855 | J32: 2.9752891 | K32: 1.147227 | L32: =B32-2014 -> 1 | M32: =VLOOKUP(A32,Sheet2!$B$2:$E$186,2,FALSE) -> 6 | N32: Americas | O32: South America | P32: 1 | Q32: 0 | R32: 0 | S32: 0 | T32: 0 | U32: 0 | V32: 0 | W32: 0 | X32: 0 | Y32: 1 | Z32: 0 | AA32: 0 | AB32: 0 | AC32: 0 | AD32: 0 | AE32: 0 | AF32: 0 | AG32: 0 | AH32: 0 | AI32: 0 | AJ32: 0 | AK32: 0 | AL32: 0 | AM32: 0 | AN32: 0
A33: Argentina | B33: 2016 | C33: 1204734.2 | D33: 4359475 | E33: 19.723175 | F33: 0.92795402 | G33: 0.11961012 | H33: 0.038749531 | I33: 14.758175 | J33: 3.0052135 | K33: 1.1401374 | L33: =B33-2014 -> 2 | M33: =VLOOKUP(A33,Sheet2!$B$2:$E$186,2,FALSE) -> 6 | N33: Americas | O33: South America | P33: 1 | Q33: 0 | R33: 0 | S33: 0 | T33: 0 | U33: 0 | V33: 0 | W33: 0 | X33: 0 | Y33: 1 | Z33: 0 | AA33: 0 | AB33: 0 | AC33: 0 | AD33: 0 | AE33: 0 | AF33: 0 | AG33: 0 | AH33: 0 | AI33: 0 | AJ33: 0 | AK33: 0 | AL33: 0 | AM33: 0 | AN33: 0
A34: Argentina | B34: 2017 | C34: 1238689.9 | D34: 4468098.5 | E34: 20.033661 | F34: 0.95406014 | G34: 0.12297056 | H34: 0.039081357 | I34: 16.562707 | J34: 3.0354388 | K34: 1.1736989 | L34: =B34-2014 -> 3 | M34: =VLOOKUP(A34,Sheet2!$B$2:$E$186,2,FALSE) -> 6 | N34: Americas | O34: South America | P34: 1 | Q34: 0 | R34: 0 | S34: 0 | T34: 0 | U34: 0 | V34: 0 | W34: 0 | X34: 0 | Y34: 1 | Z34: 0 | AA34: 0 | AB34: 0 | AC34: 0 | AD34: 0 | AE34: 0 | AF34: 0 | AG34: 0 | AH34: 0 | AI34: 0 | AJ34: 0 | AK34: 0 | AL34: 0 | AM34: 0 | AN34: 0
A35: Argentina | B35: 2018 | C35: 1206268.2 | D35: 4558053 | E35: 20.135071 | F35: 0.97380877 | G35: 0.13046715 | H35: 0.039239753 | I35: 28.094992 | J35: 3.065968 | K35: 1.1167079 | L35: =B35-2014 -> 4 | M35: =VLOOKUP(A35,Sheet2!$B$2:$E$186,2,FALSE) -> 6 | N35: Americas | O35: South America | P35: 1 | Q35: 0 | R35: 0 | S35: 0 | T35: 0 | U35: 0 | V35: 0 | W35: 0 | X35: 0 | Y35: 1 | Z35: 0 | AA35: 0 | AB35: 0 | AC35: 0 | AD35: 0 | AE35: 0 | AF35: 0 | AG35: 0 | AH35: 0 | AI35: 0 | AJ35: 0 | AK35: 0 | AL35: 0 | AM35: 0 | AN35: 0
A36: Argentina | B36: 2019 | C36: 1182132.5 | D36: 4605820 | E36: 20.643278 | F36: 0.98147285 | G36: 0.11970478 | H36: 0.03882077 | I36: 48.147892 | J36: 3.0968044 | K36: 1.0083193 | L36: =B36-2014 -> 5 | M36: =VLOOKUP(A36,Sheet2!$B$2:$E$186,2,FALSE) -> 6 | N36: Americas | O36: South America | P36: 1 | Q36: 0 | R36: 0 | S36: 0 | T36: 0 | U36: 0 | V36: 0 | W36: 0 | X36: 0 | Y36: 1 | Z36: 0 | AA36: 0 | AB36: 0 | AC36: 0 | AD36: 0 | AE36: 0 | AF36: 0 | AG36: 0 | AH36: 0 | AI36: 0 | AJ36: 0 | AK36: 0 | AL36: 0 | AM36: 0 | AN36: 0
A37: Argentina | B37: 2020 | C37: 1065095.8 | D37: 4625739 | E37: 18.749563 | F37: 0.98176628 | G37: 0.092383638 | H37: 0.038047366 | I37: 70.539167 | J37: 3.1279507 | K37: 0.98257148 | L37: =B37-2014 -> 6 | M37: =VLOOKUP(A37,Sheet2!$B$2:$E$186,2,FALSE) -> 6 | N37: Americas | O37: South America | P37: 1 | Q37: 0 | R37: 0 | S37: 0 | T37: 0 | U37: 0 | V37: 0 | W37: 0 | X37: 0 | Y37: 1 | Z37: 0 | AA37: 0 | AB37: 0 | AC37: 0 | AD37: 0 | AE37: 0 | AF37: 0 | AG37: 0 | AH37: 0 | AI37: 0 | AJ37: 0 | AK37: 0 | AL37: 0 | AM37: 0 | AN37: 0
A38: Armenia | B38: 2015 | C38: 41846.973 | D38: 211489.77 | E38: 1.0719054 | F38: 0.83716989 | G38: 0.079937756 | H38: 0.030163603 | I38: 477.91831 | J38: 3.205678 | K38: 0.93468469 | L38: =B38-2014 -> 1 | M38: =VLOOKUP(A38,Sheet2!$B$2:$E$186,2,FALSE) -> 7 | N38: Asia | O38: Western Asia | P38: 0 | Q38: 0 | R38: 1 | S38: 0 | T38: 0 | U38: 0 | V38: 0 | W38: 0 | X38: 1 | Y38: 0 | Z38: 0 | AA38: 0 | AB38: 0 | AC38: 0 | AD38: 0 | AE38: 0 | AF38: 0 | AG38: 0 | AH38: 0 | AI38: 0 | AJ38: 0 | AK38: 0 | AL38: 0 | AM38: 0 | AN38: 0
A39: Armenia | B39: 2016 | C39: 41918.883 | D39: 215075.11 | E39: 1.0058495 | F39: 0.85499561 | G39: 0.085348748 | H39: 0.030505069 | I39: 480.48815 | J39: 3.2312896 | K39: 0.92760533 | L39: =B39-2014 -> 2 | M39: =VLOOKUP(A39,Sheet2!$B$2:$E$186,2,FALSE) -> 7 | N39: Asia | O39: Western Asia | P39: 0 | Q39: 0 | R39: 1 | S39: 0 | T39: 0 | U39: 0 | V39: 0 | W39: 0 | X39: 1 | Y39: 0 | Z39: 0 | AA39: 0 | AB39: 0 | AC39: 0 | AD39: 0 | AE39: 0 | AF39: 0 | AG39: 0 | AH39: 0 | AI39: 0 | AJ39: 0 | AK39: 0 | AL39: 0 | AM39: 0 | AN39: 0
A40: Armenia | B40: 2017 | C40: 45075.051 | D40: 219472.14 | E40: 1.012529 | F40: 0.87775975 | G40: 0.095580965 | H40: 0.030879976 | I40: 482.71639 | J40: 3.1257348 | K40: 1.03466 | L40: =B40-2014 -> 3 | M40: =VLOOKUP(A40,Sheet2!$B$2:$E$186,2,FALSE) -> 7 | N40: Asia | O40: Western Asia | P40: 0 | Q40: 0 | R40: 1 | S40: 0 | T40: 0 | U40: 0 | V40: 0 | W40: 0 | X40: 1 | Y40: 0 | Z40: 0 | AA40: 0 | AB40: 0 | AC40: 0 | AD40: 0 | AE40: 0 | AF40: 0 | AG40: 0 | AH40: 0 | AI40: 0 | AJ40: 0 | AK40: 0 | AL40: 0 | AM40: 0 | AN40: 0
...

Sheet Sheet2
B1: Pais | D1: continent | E1: subregion
B2: Aruba | C2: 1 | D2: Americas | E2: Caribbean
B3: Angola | C3: 2 | D3: Africa | E3: Middle Africa | I3: subregion
B4: Anguilla | C4: 3 | D4: Americas | E4: Caribbean | I4: Caribbean
B5: Albania | C5: 4 | D5: Europe | E5: Southern Europe | I5: Middle Africa
B6: United Arab Emirates | C6: 5 | D6: Asia | E6: Western Asia | I6: Southern Europe
B7: Argentina | C7: 6 | D7: Americas | E7: South America | I7: Western Asia
B8: Armenia | C8: 7 | D8: Asia | E8: Western Asia | I8: South America
B9: Antigua and Barbuda | C9: 8 | D9: Americas | E9: Caribbean | I9: Australia and New Zealand
B10: Australia | C10: 9 | D10: Oceania | E10: Australia and New Zealand | I10: Western Europe
B11: Austria | C11: 10 | D11: Europe | E11: Western Europe | I11: Eastern Africa
B12: Azerbaijan | C12: 11 | D12: Asia | E12: Western Asia | I12: Western Africa
B13: Burundi | C13: 12 | D13: Africa | E13: Eastern Africa | I13: Southern Asia
B14: Belgium | C14: 13 | D14: Europe | E14: Western Europe | I14: Eastern Europe
... B23: Belize | C23: 22 | D23: Americas | E23: Central America | I23: Central Asia
B24: Bermuda | C24: 23 | D24: Americas | E24: Northern America
B25: Bolivia (Plurinational State of) | C25: 24 | D25: Americas | E25: South America
B26: Brazil | C26: 25 | D26: Americas | E26: South America
B27: Barbados | C27: 26 | D27: Americas | E27: Caribbean
B28: Brunei Darussalam | C28: 27 | D28: Asia | E28: South-eastern Asia
B29: Bhutan | C29: 28 | D29: Asia | E29: Southern Asia
B30: Botswana | C30: 29 | D30: Africa | E30: Southern Africa
B31: Central African Republic | C31: 30 | D31: Africa | E31: Middle Africa
B32: Canada | C32: 31 | D32: Americas | E32: Northern America
B33: Switzerland | C33: 32 | D33: Europe | E33: Western Europe
B34: Chile | C34: 33 | D34: Americas | E34: South America
B35: China | C35: 34 | D35: Asia | E35: Eastern Asia
... B186: Zimbabwe | C186: 185 | D186: Africa | E186: Eastern Africa

Sheet Sheet1
A1: country | B1: year | C1: pop | D1: avh | E1: currency_unit | G1: ccon | H1: cda | I1: cgdpe | J1: cgdpo | K1: cn | L1: ck | M1: ctfp | N1: cwtfp | O1: rconna | P1: rdana | Q1: rtfpna | R1: labsh | S1: pl_con | T1: pl_da | U1: pl_gdpo | W1: i_cig | X1: i_xm | Y1: i_xr | Z1: i_outlier | AA1: i_irr | AC1: cor_exp | AD1: csh_c | AE1: csh_i | AF1: csh_g | AG1: csh_x | AH1: csh_m | AI1: csh_r | AJ1: pl_c | AK1: pl_i | AL1: pl_g | AM1: pl_x | AN1: pl_m | AO1: pl_n | AP1: pl_k
A2: Aruba | B2: 2015 | C2: 0.104184 | E2: Aruban Guilder | G2: 3350.3652 | H2: 4413.416 | I2: 4407.7729 | J2: 4417.959 | K2: 24339.127 | L2: 0.00027220347 | O2: 3542.0283 | P2: 4549.6416 | R2: 0.64510614 | S2: 0.6950047 | T2: 0.67219996 | U2: 0.67065018 | W2: ICP PPP timeseries: benchmark or interpolated | X2: Benchmark | Y2: Market-based | Z2: Regular | AA2: Regular | AC2: 0.64919718 | AD2: 0.5058338 | AE2: 0.24062037 | AF2: 0.25251755 | AG2: 0.9143573 | AH2: -0.9133271 | AI2: -1.8855117e-06 | AJ2: 0.7336269 | AK2: 0.60032756 | AL2: 0.61763817 | AM2: 0.53435189 | AN2: 0.53589332 | AO2: 0.51738656 | AP2: 0.51611269
A3: Aruba | B3: 2016 | C3: 0.104977 | E3: Aruban Guilder | G3: 3334.7012 | H3: 4295.2319 | I3: 4356.2686 | J3: 3770.416 | K3: 21043.992 | L3: 0.00023493066 | O3: 3525.9619 | P3: 4540.4155 | R3: 0.64510614 | S3: 0.69809848 | T3: 0.6849066 | U3: 0.79132831 | W3: ICP PPP timeseries: benchmark or interpolated | X3: Benchmark | Y3: Market-based | Z3: Regular | AA3: Regular | AC3: 0.6619148 | AD3: 0.58660871 | AE3: 0.25475457 | AF3: 0.29782978 | AG3: 1.0374159 | AH3: -1.1766089 | AI3: 1.5241377e-16 | AJ3: 0.73568942 | AK3: 0.63910783 | AL3: 0.62405894 | AM3: 0.5478375 | AN3: 0.47360492 | AO3: 0.57589978 | AP3: 0.58340216
A4: Aruba | B4: 2017 | C4: 0.105731 | E4: Aruban Guilder | G4: 3402.7212 | H4: 4367.5635 | I4: 4424.7812 | J4: 3404.4082 | K4: 18997.287 | L4: 0.00021144211 | O4: 3615.126 | P4: 4677.4575 | R4: 0.64510614 | S4: 0.71028763 | T4: 0.69888884 | U4: 0.9083606 | W4: Benchmark | X4: Benchmark | Y4: Market-based | Z4: Regular | AA4: Regular | AC4: 0.68035332 | AD4: 0.66956091 | AE4: 0.28340974 | AF4: 0.32994354 | AG4: 1.1084222 | AH4: -1.3913364 | AI4: 0 | AJ4: 0.74797729 | AK4: 0.65868858 | AL4: 0.63380319 | AM4: 0.59454268 | AN4: 0.46520603 | AO4: 0.63878196 | AP4: 0.64759034
A5: Aruba | B5: 2018 | C5: 0.106432 | E5: Aruban Guilder | G5: 3532.084 | H5: 4606.3501 | I5: 4573.9668 | J5: 4011.4839 | K5: 21126.402 | L5: 0.00022944516 | O5: 3577.8867 | P5: 4657.479 | R5: 0.64510614 | S5: 0.72632986 | T5: 0.7162677 | U5: 0.81670135 | W5: ICP PPP timeseries: benchmark or interpolated | X5: Benchmark | Y5: Market-based | Z5: Regular | AA5: Regular | AC5: 0.6717021 | AD5: 0.5748865 | AE5: 0.26779774 | AF5: 0.30560663 | AG5: 0.98418564 | AH5: -1.1324766 | AI5: -1.3880396e-16 | AJ5: 0.78468898 | AK5: 0.68318423 | AL5: 0.61654861 | AM5: 0.59957123 | AN5: 0.52616692 | AO5: 0.66503203 | AP5: 0.59917498
A6: Aruba | B6: 2019 | C6: 0.107076 | E6: Aruban Guilder | G6: 3446.5369 | H6: 4420.9092 | I6: 4471.2378 | J6: 3765.762 | K6: 20307.863 | L6: 0.00021540899 | O6: 3512.5037 | P6: 4607.1699 | R6: 0.64510614 | S6: 0.75310636 | T6: 0.75947618 | U6: 0.90175605 | W6: ICP PPP timeseries: benchmark or interpolated | X6: Extrapolated | Y6: Market-based | Z6: Regular | AA6: Regular | AC6: 0.1283387 | AD6: 0.6002509 | AE6: 0.2587451 | AF6: 0.31497875 | AG6: 1.0512038 | AH6: -1.2251786 | AI6: 1.339147e-16 | AJ6: 0.81029986 | AK6: 0.78200743 | AL6: 0.64411352 | AM6: 0.62822962 | AN6: 0.53073663 | AO6: 0.71802425 | AP6: 0.63634551
A7: Aruba | B7: 2020 | C7: 0.1074 | E7: Aruban Guilder | G7: 3182.5955 | H7: 4013.0608 | I7: 3396.522 | J7: 2899.124 | K7: 21618.939 | L7: 0.00022218531 | O7: 3090.1267 | P7: 3958.8789 | R7: 0.64510614 | S7: 0.73282403 | T7: 0.73070544 | U7: 0.85607135 | W7: ICP PPP timeseries: benchmark or interpolated | X7: Extrapolated | Y7: Market-based | Z7: Regular | AA7: Regular | AC7: 0.67309077 | AD7: 0.70879477 | AE7: 0.28645384 | AF7: 0.38898352 | AG7: 0.80953091 | AH7: -1.193763 | AI7: -2.2509752e-10 | AJ7: 0.7901543 | AK7: 0.72258635 | AL7: 0.62835847 | AM7: 0.56039184 | AN7: 0.51019263 | AO7: 0.71344411 | AP7: 0.47074407
A8: Angola | B8: 2015 | C8: 28.157798 | D8: 2100.36 | E8: Kwanza | G8: 161999.94 | H8: 237960.67 | I8: 230182.08 | J8: 239876.62 | K8: 1308671.8 | L8: 0.021371288 | M8: 0.37530184 | N8: 0.35917857 | O8: 155849.17 | P8: 208783.45 | Q8: 1.2182209 | R8: 0.3500483 | S8: 0.49616739 | T8: 0.50479013 | U8: 0.48438925 | W8: ICP PPP timeseries: benchmark or interpolated | X8: Benchmark | Y8: Market-based | Z8: Regular | AA8: Regular | AC8: 0.31993571 | AD8: 0.45709863 | AE8: 0.31666586 | AF8: 0.21824826 | AG8: 0.30944487 | AH8: -0.16115534 | AI8: -0.1403023 | AJ8: 0.55893024 | AK8: 0.52317973 | AL8: 0.36471707 | AM8: 0.45703328 | AN8: 0.55744195 | AO8: 0.30037403 | AP8: 0.47212261
A9: Angola | B9: 2016 | C9: 29.18307 | D9: 2100.35 | E9: Kwanza | G9: 157984 | H9: 213912.77 | I9: 220253.44 | J9: 225767.05 | K9: 1275201.9 | L9: 0.019563366 | M9: 0.36074704 | N9: 0.33046126 | O9: 159093.11 | P9: 198197.3 | Q9: 1.156446 | R9: 0.34245735 | S9: 0.44746372 | T9: 0.45912483 | U9: 0.44791228 | W9: ICP PPP timeseries: benchmark or interpolated | X9: Benchmark | Y9: Market-based | Z9: Regular | AA9: Regular | AC9: 0.2450921 | AD9: 0.49399149 | AE9: 0.24772777 | AF9: 0.20577402 | AG9: 0.2771318 | AH9: -0.11783896 | AI9: -0.10678615 | AJ9: 0.50799743 | AK9: 0.49206441 | AL9: 0.30214346 | AM9: 0.44843766 | AN9: 0.53930348 | AO9: 0.27747127 | AP9: 0.43994373
A10: Angola | B10: 2017 | C10: 30.234839 | D10: 2101.5 | E10: Kwanza | G10: 163518.38 | H10: 215643.44 | I10: 228802.75 | J10: 238324.33 | K10: 1534771.1 | L10: 0.022330774 | M10: 0.34203872 | N10: 0.298042 | O10: 162898.44 | P10: 188904.44 | Q10: 1.1367621 | R10: 0.34664506 | S10: 0.52367938 | T10: 0.53375173 | U10: 0.51242715 | W10: Benchmark | X10: Benchmark | Y10: Market-based | Z10: Regular | AA10: Regular | AC10: 0.20745099 | AD10: 0.46618998 | AE10: 0.21871483 | AF10: 0.219927 | AG10: 0.31370807 | AH10: -0.11685 | AI10: -0.10168993 | AJ10: 0.6285391 | AK10: 0.56534909 | AL10: 0.30140303 | AM10: 0.46686584 | AN10: 0.55523568 | AO10: 0.31530276 | AP10: 0.44579929
A11: Angola | B11: 2018 | C11: 31.297155 | D11: 2102.45 | E11: Kwanza | G11: 163980.22 | H11: 205352.83 | I11: 242431.7 | J11: 239628.8 | K11: 1268128.6 | L11: 0.018187204 | M11: 0.37376025 | N11: 0.30831915 | O11: 157809.2 | P11: 181925.8 | Q11: 1.105635 | R11: 0.33080524 | S11: 0.41310132 | T11: 0.41806915 | U11: 0.42295924 | W11: ICP PPP timeseries: benchmark or interpolated | X11: Benchmark | Y11: Market-based | Z11: Regular | AA11: Regular | AC11: 0.19317024 | AD11: 0.4971087 | AE11: 0.1726529 | AF11: 0.18720064 | AG11: 0.36783883 | AH11: -0.12062361 | AI11: -0.10417745 | AJ11: 0.47954507 | AK11: 0.43775904 | AL11: 0.23666081 | AM11: 0.47758624 | AN11: 0.55480158 | AO11: 0.25130495 | AP11: 0.44095045
A12: Angola | B12: 2019 | C12: 32.375632 | D12: 2103.92 | E12: Kwanza | G12: 152289.09 | H12: 194875.98 | I12: 255581.67 | J12: 236096.61 | K12: 1174152.9 | L12: 0.016360888 | M12: 0.37838009 | N12: 0.30053663 | O12: 155285.17 | P12: 179277.89 | Q12: 1.0791695 | R12: 0.32351938 | S12: 0.31955495 | T12: 0.32528445 | U12: 0.35213017 | W12: ICP PPP timeseries: benchmark or interpolated | X12: Extrapolated | Y12: Market-based | Z12: Regular | AA12: Regular | AC12: 0.18332453 | AD12: 0.47559974 | AE12: 0.18037909 | AF12: 0.16942897 | AG12: 0.36934426 | AH12: -0.12293855 | AI12: -0.071813546 | AJ12: 0.36972886 | AK12: 0.34577286 | AL12: 0.17871306 | AM12: 0.39554712 | AN12: 0.30232567 | AO12: 0.20433864 | AP12: 0.39098293
A13: Angola | B13: 2020 | C13: 33.451132 | D13: 2015.3 | E13: Kwanza | G13: 145932.12 | H13: 173215.09 | I13: 218663.3 | J13: 211528.89 | K13: 833200.75 | L13: 0.010847358 | M13: 0.43028635 | N13: 0.33801594 | O13: 144771.42 | P13: 167580.47 | Q13: 1.0198766 | R13: 0.28762925 | S13: 0.24788359 | T13: 0.25071004 | U13: 0.25916594 | W13: ICP PPP timeseries: benchmark or interpolated | X13: Extrapolated | Y13: Market-based | Z13: Regular | AA13: Regular | AC13: 0.17283576 | AD13: 0.55068535 | AE13: 0.12897989 | AF13: 0.13920681 | AG13: 0.35767752 | AH13: -0.1037761 | AI13: -0.072773494 | AJ13: 0.27641341 | AK13: 0.26582813 | AL13: 0.13502305 | AM13: 0.28146714 | AN13: 0.2693063 | AO13: 0.15926923 | AP13: 0.42751825
A14: Anguilla | B14: 2015 | C14: 0.01421 | E14: East Caribbean Dollar | G14: 392.36557 | H14: 500.5798 | I14: 414.86539 | J14: 227.59645 | K14: 3065.7214 | O14: 456.61096 | P14: 601.29419 | S14: 0.80375582 | T14: 0.79625446 | U14: 1.4514214 | W14: ICP PPP timeseries: benchmark or interpolated | X14: Benchmark | Y14: Market-based | Z14: Regular | AC14: 0.44860432 | AD14: 1.3186805 | AE14: 0.47546542 | AF14: 0.40527239 | AG14: 1.5594705 | AH14: -2.758889 | AI14: 1.1211846e-09 | AJ14: 0.86597404 | AK14: 0.76905571 | AL14: 0.60130942 | AM14: 0.58497888 | AN14: 0.43935531 | AO14: 0.55039811
A15: Anguilla | B15: 2016 | C15: 0.01432 | E15: East Caribbean Dollar | G15: 380.8024 | H15: 461.85297 | I15: 383.42172 | J15: 200.67546 | K15: 2877.0647 | O15: 455.62903 | P15: 573.87457 | S15: 0.83327621 | T15: 0.83053899 | U15: 1.5868741 | W15: ICP PPP timeseries: benchmark or interpolated | X15: Benchmark | Y15: Market-based | Z15: Regular | AC15: 0.37319304 | AD15: 1.462484 | AE15: 0.40388876 | AF15: 0.43511918 | AG15: 1.7653941 | AH15: -3.0668862 | AI15: 1.1630532e-09 | AJ15: 0.90537611 | AK15: 0.81767883 | AL15: 0.59094035 | AM15: 0.58442885 | AN15: 0.44225705 | AO15: 0.59873456
A16: Anguilla | B16: 2017 | C16: 0.014425 | E16: East Caribbean Dollar | G16: 245.86432 | H16: 318.96652 | I16: 313.38196 | J16: 160.17664 | K16: 2415.4243 | O16: 345.203 | P16: 457.96802 | S16: 0.90671647 | T16: 0.88992202 | U16: 1.7411126 | W16: Benchmark | X16: Benchmark | Y16: Market-based | Z16: Regular | AC16: 0.31072691 | AD16: 0.95849222 | AE16: 0.45638493 | AF16: 0.57646519 | AG16: 2.9187441 | AH16: -3.9100847 | AI16: -1.7198081e-06 | AJ16: 1.1031093 | AK16: 0.83343743 | AL16: 0.58017286 | AM16: 0.60159707 | AN16: 0.45700595 | AO16: 0.66950333
A17: Anguilla | B17: 2018 | C17: 0.014721 | E17: East Caribbean Dollar | G17: 452.10547 | H17: 637.8432 | I17: 405.2319 | J17: 150.71683 | K17: 2865.6726 | O17: 521.01086 | P17: 764.86292 | S17: 0.78753871 | T17: 0.78650969 | U17: 2.114687 | W17: ICP PPP timeseries: benchmark or interpolated | X17: Benchmark | Y17: Market-based | Z17: Regular | AC17: 0.34502 | AD17: 2.4429872 | AE17: 1.2323622 | AF17: 0.556714 | AG17: 2.4073122 | AH17: -5.6393719 | AI17: -3.6047088e-06 | AJ17: 0.84096815 | AK17: 0.78400488 | AL17: 0.55307831 | AM17: 0.6027261 | AN17: 0.47253752 | AO17: 0.63176727
A18: Anguilla | B18: 2019 | C18: 0.014823 | E18: East Caribbean Dollar | G18: 543.94049 | H18: 642.95502 | I18: 499.90405 | J18: 327.97083 | K18: 3364.373 | O18: 542.43842 | P18: 666.1535 | S18: 0.76159406 | T18: 0.75942987 | U18: 1.1575482 | W18: ICP PPP timeseries: benchmark or interpolated | X18: Extrapolated | Y18: Market-based | Z18: Regular | AC18: 0.44176354 | AD18: 1.2891868 | AE18: 0.30190033 | AF18: 0.36931577 | AG18: 1.2374808 | AH18: -2.1978869 | AI18: 3.244772e-06 | AJ18: 0.83310446 | AK18: 0.74754089 | AL18: 0.51196967 | AM18: 0.66567582 | AN18: 0.52550703 | AO18: 0.60704732
A19: Anguilla | B19: 2020 | C19: 0.014843 | E19: East Caribbean Dollar | G19: 344.61343 | H19: 444.17673 | I19: 353.12875 | J19: 238.60196 | K19: 3547.9626 | O19: 349.57336 | P19: 461.93973 | S19: 0.75221032 | T19: 0.74017113 | U19: 1.0954467 | W19: ICP PPP timeseries: benchmark or interpolated | X19: Extrapolated | Y19: Market-based | Z19: Regular | AC19: 0.48768789 | AD19: 1.0749888 | AE19: 0.41727781 | AF19: 0.36931369 | AG19: 1.2450864 | AH19: -2.1066666 | AI19: -4.1659911e-07 | AJ19: 0.84127575 | AK19: 0.69850043 | AL19: 0.49296105 | AM19: 0.6484195 | AN19: 0.51730037 | AO19: 0.56363702
A20: Albania | B20: 2015 | C20: 2.898632 | D20: 1969.74 | E20: Lek | G20: 32709.959 | H20: 40862.242 | I20: 34739.609 | J20: 36354.469 | K20: 203614.44 | L20: 0.0012815284 | M20: 0.57081419 | N20: 0.61897278 | O20: 32933.82 | P20: 41406.02 | Q20: 1.0457238 | R20: 0.86971474 | S20: 0.3195897 | T20: 0.32777792 | U20: 0.31321809 | W20: ICP PPP timeseries: benchmark or interpolated | X20: Benchmark | Y20: Market-based | Z20: Regular | AA20: Lower bound | AC20: 0.45387917 | AD20: 0.70382553 | AE20: 0.22424428 | AF20: 0.19592518 | AG20: 0.099904358 | AH20: -0.2575959 | AI20: 0.033696614 | AJ20: 0.35910964 | AK20: 0.36063202 | AL20: 0.17762152 | AM20: 0.53129762 | AN20: 0.46132717 | AO20: 0.23074751 | AP20: 0.15466557
A21: Albania | B21: 2016 | C21: 2.897867 | D21: 2059.25 | E21: Lek | G21: 32833.238 | H21: 41061.492 | I21: 34959.555 | J21: 36543.039 | K21: 211923.69 | L21: 0.0010088336 | M21: 0.56600618 | N21: 0.61488384 | O21: 33736.645 | P21: 42222.41 | Q21: 0.98269004 | R21: 0.90033895 | S21: 0.33318812 | T21: 0.33928373 | U21: 0.32458186 | W21: ICP PPP timeseries: benchmark or interpolated | X21: Benchmark | Y21: Market-based | Z21: Regular | AA21: Lower bound | AC21: 0.45353509 | AD21: 0.6972276 | AE21: 0.22516616 | AF21: 0.20125368 | AG21: 0.10202117 | AH21: -0.2793633 | AI21: 0.053694688 | AJ21: 0.3769002 | AK21: 0.3636071 | AL21: 0.18175103 | AM21: 0.52629596 | AN21: 0.45737964 | AO21: 0.23201761 | AP21: 0.15166946
A22: Albania | B22: 2017 | C22: 2.898242 | D22: 2081.27 | E22: Lek | G22: 34106.039 | H22: 42635.418 | I22: 36704.574 | J22: 37818.008 | K22: 211866.8 | L22: 0.00089439179 | M22: 0.57515758 | N22: 0.62444317 | O22: 34588.988 | P22: 43455.824 | Q22: 0.97283769 | R22: 0.91199517 | S22: 0.34778997 | T22: 0.35471687 | U22: 0.34427333 | W22: Benchmark | X22: Benchmark | Y22: Market-based | Z22: Regular | AA22: Lower bound | AC22: 0.44051428 | AD22: 0.69735813 | AE22: 0.22553749 | AF22: 0.20448843 | AG22: 0.10846572 | AH22: -0.30411464 | AI22: 0.068264835 | AJ22: 0.39300821 | AK22: 0.3824151 | AL22: 0.19358413 | AM22: 0.56103486 | AN22: 0.46029887 | AO22: 0.25104415 | AP22: 0.15983585
A23: Albania | B23: 2018 | C23: 2.894231 | D23: 2113.76 | E23: Lek | G23: 34678.332 | H23: 43431.191 | I23: 37996.098 | J23: 38011.473 | K23: 220434.62 | L23: 0.0018301244 | M23: 0.45809701 | N23: 0.50383759 | O23: 35592.652 | P23: 44502.418 | Q23: 0.96068352 | R23: 0.7012924 | S23: 0.39507458 | T23: 0.39889431 | U23: 0.39873299 | W23: ICP PPP timeseries: benchmark or interpolated | X23: Benchmark | Y23: Market-based | Z23: Regular | AA23: Outlier | AC23: 0.4637083 | AD23: 0.70883352 | AE23: 0.23026893 | AF23: 0.20347869 | AG23: 0.12954876 | AH23: -0.331339 | AI23: 0.059209157 | AJ23: 0.44499592 | AK23: 0.41402787 | AL23: 0.22116986 | AM23: 0.58400929 | AN23: 0.47172976 | AO23: 0.27439487 | AP23: 0.29250157
A24: Albania | B24: 2019 | C24: 2.88501 | D24: 2142.84 | E24: Lek | G24: 37379.434 | H24: 46194.793 | I24: 40394.258 | J24: 40734.844 | K24: 231582.16 | L24: 0.0018546589 | M24: 0.46636927 | N24: 0.50892901 | O24: 36751.117 | P24: 45582.984 | Q24: 0.94389987 | R24: 0.70630348 | S24: 0.376387 | T24: 0.3812874 | U24: 0.37809944 | W24: ICP PPP timeseries: benchmark or interpolated | X24: Extrapolated | Y24: Market-based | Z24: Regular | AA24: Outlier | AC24: 0.46545727 | AD24: 0.71331429 | AE24: 0.21640836 | AF24: 0.20431378 | AG24: 0.12574998 | AH24: -0.31778541 | AI24: 0.057998966 | AJ24: 0.42404923 | AK24: 0.40206646 | AL24: 0.20998531 | AM24: 0.56568009 | AN24: 0.46370283 | AO24: 0.26456523 | AP24: 0.27741072
A25: Albania | B25: 2020 | C25: 2.871954 | D25: 2042.15 | E25: Lek | G25: 36072.754 | H25: 44582.551 | I25: 38612.836 | J25: 39250.395 | K25: 235767.41 | L25: 0.0017614752 | M25: 0.47289622 | N25: 0.51528835 | O25: 35721.066 | P25: 44284.477 | Q25: 0.96712697 | R25: 0.70489013 | S25: 0.38879296 | T25: 0.39268637 | U25: 0.38630781 | W25: ICP PPP timeseries: benchmark or interpolated | X25: Extrapolated | Y25: Market-based | Z25: Regular | AA25: Regular | AC25: 0.49842746 | AD25: 0.71112096 | AE25: 0.21680793 | AF25: 0.20792082 | AG25: 0.093571797 | AH25: -0.2607618 | AI25: 0.03134029 | AJ25: 0.43810445 | AK25: 0.40919026 | AL25: 0.2201401 | AM25: 0.56217903 | AN25: 0.4772017 | AO25: 0.27013701 | AP25: 0.30165437
A26: United Arab Emirates | B26: 2015 | C26: 8.674633 | D26: 2661.13 | E26: UAE Dirham | G26: 301829.94 | H26: 514499.75 | I26: 678574.94 | J26: 745924.06 | K26: 4267525 | O26: 257413.48 | P26: 467805.12 | S26: 0.65624332 | T26: 0.54566634 | U26: 0.49639833 | W26: ICP PPP timeseries: benchmark or interpolated | X26: Benchmark | Y26: Market-based | Z26: Regular | AC26: 0.48503289 | AD26: 0.31057051 | AE26: 0.28510919 | AF26: 0.094068475 | AG26: 0.78917432 | AH26: -0.68438107 | AI26: 0.20545858 | AJ26: 0.66287433 | AK26: 0.38873071 | AL26: 0.63435089 | AM26: 0.5104422 | AN26: 0.56224698 | AO26: 0.24804732
A27: United Arab Emirates | B27: 2016 | C27: 9.030873 | D27: 2671.65 | E27: UAE Dirham | G27: 296153.88 | H27: 502406.81 | I27: 664114.88 | J27: 712997.25 | K27: 4423458.5 | O27: 264706.22 | P27: 477193.91 | S27: 0.67347813 | T27: 0.5560112 | U27: 0.51789171 | W27: ICP PPP timeseries: benchmark or interpolated | X27: Benchmark | Y27: Market-based | Z27: Regular | AC27: 0.47422924 | AD27: 0.32240972 | AE27: 0.28927591 | AF27: 0.092954963 | AG27: 0.80707246 | AH27: -0.68948567 | AI27: 0.17777264 | AJ27: 0.67308908 | AK27: 0.38734323 | AL27: 0.6748274 | AM27: 0.51273251 | AN27: 0.5508101 | AO27: 0.24265495
A28: United Arab Emirates | B28: 2017 | C28: 9.234327 | D28: 2680.97 | E28: UAE Dirham | G28: 301245.66 | H28: 509670.34 | I28: 677643.25 | J28: 665583.12 | K28: 4332636 | O28: 282405.62 | P28: 500271.31 | S28: 0.69912565 | T28: 0.57628673 | U28: 0.58672887 | W28: Benchmark | X28: Benchmark | Y28: Market-based | Z28: Regular | AC28: 0.44677402 | AD28: 0.34894389 | AE28: 0.31314597 | AF28: 0.10366024 | AG28: 0.81978709 | AH28: -0.69034332 | AI28: 0.10480613 | AJ28: 0.68745671 | AK28: 0.39874209 | AL28: 0.73840589 | AM28: 0.5746665 | AN28: 0.56082207 | AO28: 0.24660262
A29: United Arab Emirates | B29: 2018 | C29: 9.34687 | D29: 2691.72 | E29: UAE Dirham | G29: 323638.12 | H29: 524562.94 | I29: 726452.75 | J29: 715894.12 | K29: 4057753.2 | O29: 285402.03 | P29: 502843.28 | S29: 0.66475415 | T29: 0.58785576 | U29: 0.59652603 | W29: ICP PPP timeseries: benchmark or interpolated | X29: Benchmark | Y29: Market-based | Z29: Regular | AC29: 0.44480802 | AD29: 0.34736165 | AE29: 0.28066275 | AF29: 0.10471378 | AG29: 0.91801828 | AH29: -0.59319419 | AI29: -0.057562206 | AJ29: 0.6503128 | AK29: 0.46399227 | AL29: 0.71265972 | AM29: 0.59024304 | AN29: 0.57609272 | AO29: 0.28728068
A30: United Arab Emirates | B30: 2019 | C30: 9.377847 | D30: 2706.89 | E30: UAE Dirham | G30: 350611.22 | H30: 585491.19 | I30: 766862.44 | J30: 752255.94 | K30: 4294786.5 | O30: 304670 | P30: 531968.06 | S30: 0.62326449 | T30: 0.54506481 | U30: 0.55564821 | W30: ICP PPP timeseries: benchmark or interpolated | X30: Extrapolated | Y30: Market-based | Z30: Regular | AC30: 0.44624756 | AD30: 0.35940379 | AE30: 0.3122341 | AF30: 0.10667589 | AG30: 0.87681448 | AH30: -0.65006614 | AI30: -0.0050621568 | AJ30: 0.60592095 | AK30: 0.42833416 | AL30: 0.68169704 | AM30: 0.59032685 | AN30: 0.58975154 | AO30: 0.2658051
A31: United Arab Emirates | B31: 2020 | C31: 9.448524 | D31: 2578.15 | E31: UAE Dirham | G31: 343300.16 | H31: 559090 | I31: 659146.69 | J31: 715402.88 | K31: 5296067.5 | O31: 300064.53 | P31: 492080 | S31: 0.62597084 | T31: 0.53019011 | U31: 0.48849815 | W31: ICP PPP timeseries: benchmark or interpolated | X31: Extrapolated | Y31: Market-based | Z31: Regular | AC31: 0.44693758 | AD31: 0.35611299 | AE31: 0.30163401 | AF31: 0.12375668 | AG31: 0.93779188 | AH31: -0.7087093 | AI31: -0.010586209 | AJ31: 0.63528247 | AK31: 0.37781243 | AL31: 0.5991763 | AM31: 0.50212574 | AN31: 0.55250496 | AO31: 0.23140235
A32: Argentina | B32: 2015 | C32: 43.477012 | D32: 1703.47 | E32: Argentine Peso | G32: 856482.06 | H32: 1003833.5 | I32: 993157.81 | J32: 990410.88 | K32: 3512942.2 | L32: 0.032983799 | M32: 0.80210978 | N32: 0.78431916 | O32: 1076830.9 | P32: 1249257.6 | Q32: 1.1200236 | R32: 0.57141292 | S32: 0.63252449 | T32: 0.64934617 | U32: 0.65114719 | W32: ICP PPP timeseries: extrapolated | X32: Benchmark | Y32: Market-based | Z32: Regular | AA32: Regular | AC32: 0.6612657 | AD32: 0.57202488 | AE32: 0.1487781 | AF32: 0.29274964 | AG32: 0.09957017 | AH32: -0.10767496 | AI32: -0.0054478184 | AJ32: 0.7502191 | AK32: 0.74712215 | AL32: 0.40255241 | AM32: 0.57581234 | AN32: 0.56452984 | AO32: 0.47153667 | AP32: 1.1195796
A33: Argentina | B33: 2016 | C33: 43.900313 | D33: 1646.51 | E33: Argentine Peso | G33: 856016 | H33: 1004675.8 | I33: 994337.62 | J33: 992343.31 | K33: 3481090.5 | L33: 0.031722989 | M33: 0.82316399 | N33: 0.80573499 | O33: 1069016.6 | P33: 1230656.5 | Q33: 1.1064203 | R33: 0.58497977 | S33: 0.5430398 | T33: 0.56070721 | U33: 0.5618341 | W33: ICP PPP timeseries: extrapolated | X33: Benchmark | Y33: Market-based | Z33: Regular | AA33: Regular | AC33: 0.64197086 | AD33: 0.56970251 | AE33: 0.14980675 | AF33: 0.29291832 | AG33: 0.10293377 | AH33: -0.10143358 | AI33: -0.013927784 | AJ33: 0.64814177 | AK33: 0.66244034 | AL33: 0.33862491 | AM33: 0.56663549 | AN33: 0.55545902 | AO33: 0.40308094 | AP33: 0.94412279
A34: Argentina | B34: 2017 | C34: 44.288894 | D34: 1648.81 | E34: Argentine Peso | G34: 981888.5 | H34: 1150152.8 | I34: 1120471.1 | J34: 1116606.6 | K34: 3665912.8 | L34: 0.032834984 | M34: 0.88469374 | N34: 0.8775714 | O34: 1110025 | P34: 1301974.1 | Q34: 1.1069436 | R34: 0.5848015 | S34: 0.55348146 | T34: 0.57442659 | U34: 0.57641464 | W34: Benchmark | X34: Benchmark | Y34: Market-based | Z34: Regular | AA34: Regular | AC34: 0.66124429 | AD34: 0.64904249 | AE34: 0.15069254 | AF34: 0.23030792 | AG34: 0.090484016 | AH34: -0.10726649 | AI34: -0.013260498 | AJ34: 0.59271415 | AK34: 0.69664961 | AL34: 0.44291783 | AM34: 0.57786077 | AN34: 0.55854386 | AO34: 0.4373332 | AP34: 1.0154245
A35: Argentina | B35: 2018 | C35: 44.654882 | D35: 1638.44 | E35: Argentine Peso | G35: 1034199.4 | H35: 1186254.6 | I35: 1164259.9 | J35: 1160582.1 | K35: 3878835.8 | L35: 0.033986915 | M35: 0.88697791 | N35: 0.87269133 | O35: 1085872.6 | P35: 1256070 | Q35: 1.0631099 | R35: 0.54064101 | S35: 0.43274209 | T35: 0.45077556 | U35: 0.45220405 | W35: ICP PPP timeseries: benchmark or interpolated | X35: Benchmark | Y35: Market-based | Z35: Regular | AA35: Regular | AC35: 0.67027525 | AD35: 0.66887337 | AE35: 0.13101634 | AF35: 0.22223067 | AG35: 0.088707119 | AH35: -0.099333867 | AI35: -0.01149366 | AJ35: 0.4696658 | AK35: 0.57342967 | AL35: 0.32160856 | AM35: 0.59793317 | AN35: 0.56764454 | AO35: 0.35660461 | AP35: 0.83871895
A36: Argentina | B36: 2019 | C36: 44.973465 | D36: 1612.12 | E36: Argentine Peso | G36: 965162.12 | H36: 1089028.8 | I36: 1125252.2 | J36: 1106826.1 | K36: 4035455 | L36: 0.034166362 | M36: 0.82013255 | N36: 0.77650511 | O36: 1018771.2 | P36: 1149789.2 | Q36: 1.0276719 | R36: 0.53303313 | S36: 0.38305974 | T36: 0.39791495 | U36: 0.40453929 | W36: ICP PPP timeseries: benchmark or interpolated | X36: Extrapolated | Y36: Market-based | Z36: Regular | AA36: Regular | AC36: 0.66640297 | AD36: 0.64411306 | AE36: 0.11191157 | AF36: 0.22789575 | AG36: 0.10265765 | AH36: -0.083059922 | AI36: -0.0035180829 | AJ36: 0.41531853 | AK36: 0.51366591 | AL36: 0.29188511 | AM36: 0.57306582 | AN36: 0.53435755 | AO36: 0.31710184 | AP36: 0.69605541
A37: Argentina | B37: 2020 | C37: 45.191965 | D37: 1528.56 | E37: Argentine Peso | G37: 906039.75 | H37: 1021121.6 | I37: 1052780 | J37: 1036080.4 | K37: 4382449.5 | L37: 0.034554478 | M37: 0.80493891 | N37: 0.76104486 | O37: 914742.94 | P37: 1038720.4 | Q37: 0.9987635 | R37: 0.55504137 | S37: 0.35156924 | T37: 0.36640179 | U37: 0.37230751 | W37: ICP PPP timeseries: benchmark or interpolated | X37: Extrapolated | Y37: Market-based | Z37: Regular | AA37: Regular | AC37: 0.65604007 | AD37: 0.63054806 | AE37: 0.11107425 | AF37: 0.24393973 | AG37: 0.090038076 | AH37: -0.072404414 | AI37: -0.0031957491 | AJ37: 0.38795383 | AK37: 0.48317863 | AL37: 0.25752045 | AM37: 0.5570628 | AN37: 0.52167106 | AO37: 0.29202244 | AP37: 0.58984172
A38: Armenia | B38: 2015 | C38: 2.921177 | D38: 1868.85 | E38: Armenian Dram | G38: 33434.883 | H38: 37129.348 | I38: 33222.996 | J38: 34416.961 | K38: 93613.266 | L38: 0.00092647818 | M38: 0.63778061 | N38: 0.66378677 | O38: 36979.742 | P38: 43461.52 | Q38: 0.92769188 | R38: 0.57366437 | S38: 0.28731769 | T38: 0.31765157 | U38: 0.30663189 | W38: ICP PPP timeseries: benchmark or interpolated | X38: Benchmark | Y38: Market-based | Z38: Regular | AA38: Regular | AC38: 0.56740049 | AD38: 0.72941017 | AE38: 0.10734432 | AF38: 0.24205518 | AG38: 0.075392112 | AH38: -0.20474862 | AI38: 0.050546926 | AJ38: 0.32754525 | AK38: 0.59217305 | AL38: 0.16609576 | AM38: 0.57140666 | AN38: 0.46218896 | AO38: 0.42383936 | AP38: 0.64882606
A39: Armenia | B39: 2016 | C39: 2.918793 | D39: 1857.71 | E39: Armenian Dram | G39: 34953.941 | H39: 38378.367 | I39: 35610.266 | J39: 37252.52 | K39: 95791.75 | L39: 0.00093957502 | M39: 0.70407033 | N39: 0.70127589 | O39: 36199.109 | P39: 42024.547 | Q39: 0.95378256 | R39: 0.56517243 | S39: 0.27081299 | T39: 0.29615441 | U39: 0.28309858 | W39: ICP PPP timeseries: benchmark or interpolated | X39: Benchmark | Y39: Market-based | Z39: Regular | AA39: Regular | AC39: 0.56618643 | AD39: 0.69992703 | AE39: 0.091924623 | AF39: 0.23837033 | AG39: 0.086889699 | AH39: -0.17314008 | AI39: 0.056028385 | AJ39: 0.30862443 | AK39: 0.55482035 | AL39: 0.15978723 | AM39: 0.55850101 | AN39: 0.4989931 | AO39: 0.3997457 | AP39: 0.63174564
A40: Armenia | B40: 2017 | C40: 2.914963 | D40: 1862.92 | E40: Armenian Dram | G40: 41024.148 | H40: 44961.586 | I40: 40589.934 | J40: 42776.336 | K40: 99837.773 | L40: 0.0009797879 | M40: 0.79629064 | N40: 0.80601597 | O40: 40392.848 | P40: 46799.176 | Q40: 1.0272477 | R40: 0.5487541 | S40: 0.25949207 | T40: 0.28399798 | U40: 0.26948214 | W40: Benchmark | X40: Benchmark | Y40: Market-based | Z40: Regular | AA40: Regular | AC40: 0.56215734 | AD40: 0.72986591 | AE40: 0.092047103 | AF40: 0.22917247 | AG40: 0.086796537 | AH40: -0.18185973 | AI40: 0.043977764 | AJ40: 0.2954879 | AK40: 0.53932499 | AL40: 0.14485291 | AM40: 0.57771522 | AN40: 0.50048953 | AO40: 0.39615992 | AP40: 0.66238153
...
